[2022-02-02 19:10:07,010] {taskinstance.py:1032} INFO - Dependencies all met for <TaskInstance: ex_1_data_ingestion_gcs_dag_v3.local_to_gcs_task scheduled__2021-06-01T00:00:00+00:00 [queued]>
[2022-02-02 19:10:07,023] {taskinstance.py:1032} INFO - Dependencies all met for <TaskInstance: ex_1_data_ingestion_gcs_dag_v3.local_to_gcs_task scheduled__2021-06-01T00:00:00+00:00 [queued]>
[2022-02-02 19:10:07,024] {taskinstance.py:1238} INFO - 
--------------------------------------------------------------------------------
[2022-02-02 19:10:07,025] {taskinstance.py:1239} INFO - Starting attempt 1 of 1
[2022-02-02 19:10:07,026] {taskinstance.py:1240} INFO - 
--------------------------------------------------------------------------------
[2022-02-02 19:10:07,039] {taskinstance.py:1259} INFO - Executing <Task(PythonOperator): local_to_gcs_task> on 2021-06-01 00:00:00+00:00
[2022-02-02 19:10:07,046] {standard_task_runner.py:52} INFO - Started process 11717 to run task
[2022-02-02 19:10:07,051] {standard_task_runner.py:76} INFO - Running: ['***', 'tasks', 'run', 'ex_1_data_ingestion_gcs_dag_v3', 'local_to_gcs_task', 'scheduled__2021-06-01T00:00:00+00:00', '--job-id', '391', '--raw', '--subdir', 'DAGS_FOLDER/data_ingestion_hw_1_ex.py', '--cfg-path', '/tmp/tmp7vuyq0pf', '--error-file', '/tmp/tmp82vlfsun']
[2022-02-02 19:10:07,054] {standard_task_runner.py:77} INFO - Job 391: Subtask local_to_gcs_task
[2022-02-02 19:10:07,142] {logging_mixin.py:109} INFO - Running <TaskInstance: ex_1_data_ingestion_gcs_dag_v3.local_to_gcs_task scheduled__2021-06-01T00:00:00+00:00 [running]> on host 700aeb16bae0
[2022-02-02 19:10:07,188] {warnings.py:110} WARNING - /home/***/.local/lib/python3.7/site-packages/***/utils/context.py:152: AirflowContextDeprecationWarning: Accessing 'execution_date' from the template is deprecated and will be removed in a future version. Please use 'data_interval_start' or 'logical_date' instead.
  warnings.warn(_create_deprecation_warning(key, self._deprecation_replacements[key]))

[2022-02-02 19:10:07,217] {taskinstance.py:1426} INFO - Exporting the following env vars:
AIRFLOW_CTX_DAG_OWNER=***
AIRFLOW_CTX_DAG_ID=ex_1_data_ingestion_gcs_dag_v3
AIRFLOW_CTX_TASK_ID=local_to_gcs_task
AIRFLOW_CTX_EXECUTION_DATE=2021-06-01T00:00:00+00:00
AIRFLOW_CTX_DAG_RUN_ID=scheduled__2021-06-01T00:00:00+00:00
[2022-02-02 19:10:12,512] {python.py:175} INFO - Done. Returned value was: None
[2022-02-02 19:10:12,533] {taskinstance.py:1277} INFO - Marking task as SUCCESS. dag_id=ex_1_data_ingestion_gcs_dag_v3, task_id=local_to_gcs_task, execution_date=20210601T000000, start_date=20220202T191007, end_date=20220202T191012
[2022-02-02 19:10:12,578] {local_task_job.py:154} INFO - Task exited with return code 0
[2022-02-02 19:10:12,616] {local_task_job.py:264} INFO - 0 downstream tasks scheduled from follow-on schedule check
[2022-02-10 14:52:50,026] {taskinstance.py:1032} INFO - Dependencies all met for <TaskInstance: ex_1_data_ingestion_gcs_dag_v3.local_to_gcs_task scheduled__2021-06-01T00:00:00+00:00 [queued]>
[2022-02-10 14:52:50,081] {taskinstance.py:1032} INFO - Dependencies all met for <TaskInstance: ex_1_data_ingestion_gcs_dag_v3.local_to_gcs_task scheduled__2021-06-01T00:00:00+00:00 [queued]>
[2022-02-10 14:52:50,085] {taskinstance.py:1238} INFO - 
--------------------------------------------------------------------------------
[2022-02-10 14:52:50,087] {taskinstance.py:1239} INFO - Starting attempt 1 of 1
[2022-02-10 14:52:50,091] {taskinstance.py:1240} INFO - 
--------------------------------------------------------------------------------
[2022-02-10 14:52:50,138] {taskinstance.py:1259} INFO - Executing <Task(PythonOperator): local_to_gcs_task> on 2021-06-01 00:00:00+00:00
[2022-02-10 14:52:50,156] {standard_task_runner.py:52} INFO - Started process 3438 to run task
[2022-02-10 14:52:50,171] {standard_task_runner.py:76} INFO - Running: ['***', 'tasks', 'run', 'ex_1_data_ingestion_gcs_dag_v3', 'local_to_gcs_task', 'scheduled__2021-06-01T00:00:00+00:00', '--job-id', '745', '--raw', '--subdir', 'DAGS_FOLDER/data_ingestion_hw_1_ex.py', '--cfg-path', '/tmp/tmph_z13hm4', '--error-file', '/tmp/tmpevqoqc0_']
[2022-02-10 14:52:50,177] {standard_task_runner.py:77} INFO - Job 745: Subtask local_to_gcs_task
[2022-02-10 14:52:50,377] {logging_mixin.py:109} INFO - Running <TaskInstance: ex_1_data_ingestion_gcs_dag_v3.local_to_gcs_task scheduled__2021-06-01T00:00:00+00:00 [running]> on host e30f201fae61
[2022-02-10 14:52:50,476] {warnings.py:110} WARNING - /home/***/.local/lib/python3.7/site-packages/***/utils/context.py:152: AirflowContextDeprecationWarning: Accessing 'execution_date' from the template is deprecated and will be removed in a future version. Please use 'data_interval_start' or 'logical_date' instead.
  warnings.warn(_create_deprecation_warning(key, self._deprecation_replacements[key]))

[2022-02-10 14:52:50,532] {taskinstance.py:1426} INFO - Exporting the following env vars:
AIRFLOW_CTX_DAG_OWNER=***
AIRFLOW_CTX_DAG_ID=ex_1_data_ingestion_gcs_dag_v3
AIRFLOW_CTX_TASK_ID=local_to_gcs_task
AIRFLOW_CTX_EXECUTION_DATE=2021-06-01T00:00:00+00:00
AIRFLOW_CTX_DAG_RUN_ID=scheduled__2021-06-01T00:00:00+00:00
[2022-02-10 14:52:52,196] {taskinstance.py:1700} ERROR - Task failed with exception
Traceback (most recent call last):
  File "/home/airflow/.local/lib/python3.7/site-packages/urllib3/connectionpool.py", line 706, in urlopen
    chunked=chunked,
  File "/home/airflow/.local/lib/python3.7/site-packages/urllib3/connectionpool.py", line 445, in _make_request
    six.raise_from(e, None)
  File "<string>", line 3, in raise_from
  File "/home/airflow/.local/lib/python3.7/site-packages/urllib3/connectionpool.py", line 440, in _make_request
    httplib_response = conn.getresponse()
  File "/usr/local/lib/python3.7/http/client.py", line 1373, in getresponse
    response.begin()
  File "/usr/local/lib/python3.7/http/client.py", line 319, in begin
    version, status, reason = self._read_status()
  File "/usr/local/lib/python3.7/http/client.py", line 288, in _read_status
    raise RemoteDisconnected("Remote end closed connection without"
http.client.RemoteDisconnected: Remote end closed connection without response

During handling of the above exception, another exception occurred:

Traceback (most recent call last):
  File "/home/airflow/.local/lib/python3.7/site-packages/requests/adapters.py", line 449, in send
    timeout=timeout
  File "/home/airflow/.local/lib/python3.7/site-packages/urllib3/connectionpool.py", line 756, in urlopen
    method, url, error=e, _pool=self, _stacktrace=sys.exc_info()[2]
  File "/home/airflow/.local/lib/python3.7/site-packages/urllib3/util/retry.py", line 532, in increment
    raise six.reraise(type(error), error, _stacktrace)
  File "/home/airflow/.local/lib/python3.7/site-packages/urllib3/packages/six.py", line 769, in reraise
    raise value.with_traceback(tb)
  File "/home/airflow/.local/lib/python3.7/site-packages/urllib3/connectionpool.py", line 706, in urlopen
    chunked=chunked,
  File "/home/airflow/.local/lib/python3.7/site-packages/urllib3/connectionpool.py", line 445, in _make_request
    six.raise_from(e, None)
  File "<string>", line 3, in raise_from
  File "/home/airflow/.local/lib/python3.7/site-packages/urllib3/connectionpool.py", line 440, in _make_request
    httplib_response = conn.getresponse()
  File "/usr/local/lib/python3.7/http/client.py", line 1373, in getresponse
    response.begin()
  File "/usr/local/lib/python3.7/http/client.py", line 319, in begin
    version, status, reason = self._read_status()
  File "/usr/local/lib/python3.7/http/client.py", line 288, in _read_status
    raise RemoteDisconnected("Remote end closed connection without"
urllib3.exceptions.ProtocolError: ('Connection aborted.', RemoteDisconnected('Remote end closed connection without response'))

During handling of the above exception, another exception occurred:

Traceback (most recent call last):
  File "/home/airflow/.local/lib/python3.7/site-packages/airflow/models/taskinstance.py", line 1329, in _run_raw_task
    self._execute_task_with_callbacks(context)
  File "/home/airflow/.local/lib/python3.7/site-packages/airflow/models/taskinstance.py", line 1455, in _execute_task_with_callbacks
    result = self._execute_task(context, self.task)
  File "/home/airflow/.local/lib/python3.7/site-packages/airflow/models/taskinstance.py", line 1511, in _execute_task
    result = execute_callable(context=context)
  File "/home/airflow/.local/lib/python3.7/site-packages/airflow/operators/python.py", line 174, in execute
    return_value = self.execute_callable()
  File "/home/airflow/.local/lib/python3.7/site-packages/airflow/operators/python.py", line 185, in execute_callable
    return self.python_callable(*self.op_args, **self.op_kwargs)
  File "/opt/airflow/dags/data_ingestion_hw_1_ex.py", line 53, in upload_to_gcs
    blob.upload_from_filename(local_file)
  File "/home/airflow/.local/lib/python3.7/site-packages/google/cloud/storage/blob.py", line 2735, in upload_from_filename
    retry=retry,
  File "/home/airflow/.local/lib/python3.7/site-packages/google/cloud/storage/blob.py", line 2594, in upload_from_file
    retry=retry,
  File "/home/airflow/.local/lib/python3.7/site-packages/google/cloud/storage/blob.py", line 2412, in _do_upload
    retry=retry,
  File "/home/airflow/.local/lib/python3.7/site-packages/google/cloud/storage/blob.py", line 2242, in _do_resumable_upload
    response = upload.transmit_next_chunk(transport, timeout=timeout)
  File "/home/airflow/.local/lib/python3.7/site-packages/google/resumable_media/requests/upload.py", line 516, in transmit_next_chunk
    retriable_request, self._get_status_code, self._retry_strategy
  File "/home/airflow/.local/lib/python3.7/site-packages/google/resumable_media/requests/_request_helpers.py", line 170, in wait_and_retry
    raise error
  File "/home/airflow/.local/lib/python3.7/site-packages/google/resumable_media/requests/_request_helpers.py", line 147, in wait_and_retry
    response = func()
  File "/home/airflow/.local/lib/python3.7/site-packages/google/resumable_media/requests/upload.py", line 508, in retriable_request
    method, url, data=payload, headers=headers, timeout=timeout
  File "/home/airflow/.local/lib/python3.7/site-packages/google/auth/transport/requests.py", line 486, in request
    **kwargs
  File "/home/airflow/.local/lib/python3.7/site-packages/requests/sessions.py", line 542, in request
    resp = self.send(prep, **send_kwargs)
  File "/home/airflow/.local/lib/python3.7/site-packages/requests/sessions.py", line 655, in send
    r = adapter.send(request, **kwargs)
  File "/home/airflow/.local/lib/python3.7/site-packages/requests/adapters.py", line 498, in send
    raise ConnectionError(err, request=request)
requests.exceptions.ConnectionError: ('Connection aborted.', RemoteDisconnected('Remote end closed connection without response'))
[2022-02-10 14:52:52,355] {taskinstance.py:1277} INFO - Marking task as FAILED. dag_id=ex_1_data_ingestion_gcs_dag_v3, task_id=local_to_gcs_task, execution_date=20210601T000000, start_date=20220210T145250, end_date=20220210T145252
[2022-02-10 14:52:52,411] {standard_task_runner.py:92} ERROR - Failed to execute job 745 for task local_to_gcs_task
Traceback (most recent call last):
  File "/home/airflow/.local/lib/python3.7/site-packages/urllib3/connectionpool.py", line 706, in urlopen
    chunked=chunked,
  File "/home/airflow/.local/lib/python3.7/site-packages/urllib3/connectionpool.py", line 445, in _make_request
    six.raise_from(e, None)
  File "<string>", line 3, in raise_from
  File "/home/airflow/.local/lib/python3.7/site-packages/urllib3/connectionpool.py", line 440, in _make_request
    httplib_response = conn.getresponse()
  File "/usr/local/lib/python3.7/http/client.py", line 1373, in getresponse
    response.begin()
  File "/usr/local/lib/python3.7/http/client.py", line 319, in begin
    version, status, reason = self._read_status()
  File "/usr/local/lib/python3.7/http/client.py", line 288, in _read_status
    raise RemoteDisconnected("Remote end closed connection without"
http.client.RemoteDisconnected: Remote end closed connection without response

During handling of the above exception, another exception occurred:

Traceback (most recent call last):
  File "/home/airflow/.local/lib/python3.7/site-packages/requests/adapters.py", line 449, in send
    timeout=timeout
  File "/home/airflow/.local/lib/python3.7/site-packages/urllib3/connectionpool.py", line 756, in urlopen
    method, url, error=e, _pool=self, _stacktrace=sys.exc_info()[2]
  File "/home/airflow/.local/lib/python3.7/site-packages/urllib3/util/retry.py", line 532, in increment
    raise six.reraise(type(error), error, _stacktrace)
  File "/home/airflow/.local/lib/python3.7/site-packages/urllib3/packages/six.py", line 769, in reraise
    raise value.with_traceback(tb)
  File "/home/airflow/.local/lib/python3.7/site-packages/urllib3/connectionpool.py", line 706, in urlopen
    chunked=chunked,
  File "/home/airflow/.local/lib/python3.7/site-packages/urllib3/connectionpool.py", line 445, in _make_request
    six.raise_from(e, None)
  File "<string>", line 3, in raise_from
  File "/home/airflow/.local/lib/python3.7/site-packages/urllib3/connectionpool.py", line 440, in _make_request
    httplib_response = conn.getresponse()
  File "/usr/local/lib/python3.7/http/client.py", line 1373, in getresponse
    response.begin()
  File "/usr/local/lib/python3.7/http/client.py", line 319, in begin
    version, status, reason = self._read_status()
  File "/usr/local/lib/python3.7/http/client.py", line 288, in _read_status
    raise RemoteDisconnected("Remote end closed connection without"
urllib3.exceptions.ProtocolError: ('Connection aborted.', RemoteDisconnected('Remote end closed connection without response'))

During handling of the above exception, another exception occurred:

Traceback (most recent call last):
  File "/home/airflow/.local/lib/python3.7/site-packages/airflow/task/task_runner/standard_task_runner.py", line 85, in _start_by_fork
    args.func(args, dag=self.dag)
  File "/home/airflow/.local/lib/python3.7/site-packages/airflow/cli/cli_parser.py", line 48, in command
    return func(*args, **kwargs)
  File "/home/airflow/.local/lib/python3.7/site-packages/airflow/utils/cli.py", line 92, in wrapper
    return f(*args, **kwargs)
  File "/home/airflow/.local/lib/python3.7/site-packages/airflow/cli/commands/task_command.py", line 298, in task_run
    _run_task_by_selected_method(args, dag, ti)
  File "/home/airflow/.local/lib/python3.7/site-packages/airflow/cli/commands/task_command.py", line 107, in _run_task_by_selected_method
    _run_raw_task(args, ti)
  File "/home/airflow/.local/lib/python3.7/site-packages/airflow/cli/commands/task_command.py", line 184, in _run_raw_task
    error_file=args.error_file,
  File "/home/airflow/.local/lib/python3.7/site-packages/airflow/utils/session.py", line 70, in wrapper
    return func(*args, session=session, **kwargs)
  File "/home/airflow/.local/lib/python3.7/site-packages/airflow/models/taskinstance.py", line 1329, in _run_raw_task
    self._execute_task_with_callbacks(context)
  File "/home/airflow/.local/lib/python3.7/site-packages/airflow/models/taskinstance.py", line 1455, in _execute_task_with_callbacks
    result = self._execute_task(context, self.task)
  File "/home/airflow/.local/lib/python3.7/site-packages/airflow/models/taskinstance.py", line 1511, in _execute_task
    result = execute_callable(context=context)
  File "/home/airflow/.local/lib/python3.7/site-packages/airflow/operators/python.py", line 174, in execute
    return_value = self.execute_callable()
  File "/home/airflow/.local/lib/python3.7/site-packages/airflow/operators/python.py", line 185, in execute_callable
    return self.python_callable(*self.op_args, **self.op_kwargs)
  File "/opt/airflow/dags/data_ingestion_hw_1_ex.py", line 53, in upload_to_gcs
    blob.upload_from_filename(local_file)
  File "/home/airflow/.local/lib/python3.7/site-packages/google/cloud/storage/blob.py", line 2735, in upload_from_filename
    retry=retry,
  File "/home/airflow/.local/lib/python3.7/site-packages/google/cloud/storage/blob.py", line 2594, in upload_from_file
    retry=retry,
  File "/home/airflow/.local/lib/python3.7/site-packages/google/cloud/storage/blob.py", line 2412, in _do_upload
    retry=retry,
  File "/home/airflow/.local/lib/python3.7/site-packages/google/cloud/storage/blob.py", line 2242, in _do_resumable_upload
    response = upload.transmit_next_chunk(transport, timeout=timeout)
  File "/home/airflow/.local/lib/python3.7/site-packages/google/resumable_media/requests/upload.py", line 516, in transmit_next_chunk
    retriable_request, self._get_status_code, self._retry_strategy
  File "/home/airflow/.local/lib/python3.7/site-packages/google/resumable_media/requests/_request_helpers.py", line 170, in wait_and_retry
    raise error
  File "/home/airflow/.local/lib/python3.7/site-packages/google/resumable_media/requests/_request_helpers.py", line 147, in wait_and_retry
    response = func()
  File "/home/airflow/.local/lib/python3.7/site-packages/google/resumable_media/requests/upload.py", line 508, in retriable_request
    method, url, data=payload, headers=headers, timeout=timeout
  File "/home/airflow/.local/lib/python3.7/site-packages/google/auth/transport/requests.py", line 486, in request
    **kwargs
  File "/home/airflow/.local/lib/python3.7/site-packages/requests/sessions.py", line 542, in request
    resp = self.send(prep, **send_kwargs)
  File "/home/airflow/.local/lib/python3.7/site-packages/requests/sessions.py", line 655, in send
    r = adapter.send(request, **kwargs)
  File "/home/airflow/.local/lib/python3.7/site-packages/requests/adapters.py", line 498, in send
    raise ConnectionError(err, request=request)
requests.exceptions.ConnectionError: ('Connection aborted.', RemoteDisconnected('Remote end closed connection without response'))
[2022-02-10 14:52:52,547] {local_task_job.py:154} INFO - Task exited with return code 1
[2022-02-10 14:52:52,679] {local_task_job.py:264} INFO - 0 downstream tasks scheduled from follow-on schedule check
[2022-02-10 15:42:34,078] {taskinstance.py:1032} INFO - Dependencies all met for <TaskInstance: ex_1_data_ingestion_gcs_dag_v3.local_to_gcs_task scheduled__2021-06-01T00:00:00+00:00 [queued]>
[2022-02-10 15:42:34,092] {taskinstance.py:1032} INFO - Dependencies all met for <TaskInstance: ex_1_data_ingestion_gcs_dag_v3.local_to_gcs_task scheduled__2021-06-01T00:00:00+00:00 [queued]>
[2022-02-10 15:42:34,093] {taskinstance.py:1238} INFO - 
--------------------------------------------------------------------------------
[2022-02-10 15:42:34,094] {taskinstance.py:1239} INFO - Starting attempt 1 of 1
[2022-02-10 15:42:34,095] {taskinstance.py:1240} INFO - 
--------------------------------------------------------------------------------
[2022-02-10 15:42:34,113] {taskinstance.py:1259} INFO - Executing <Task(PythonOperator): local_to_gcs_task> on 2021-06-01 00:00:00+00:00
[2022-02-10 15:42:34,120] {standard_task_runner.py:52} INFO - Started process 1154 to run task
[2022-02-10 15:42:34,125] {standard_task_runner.py:76} INFO - Running: ['***', 'tasks', 'run', 'ex_1_data_ingestion_gcs_dag_v3', 'local_to_gcs_task', 'scheduled__2021-06-01T00:00:00+00:00', '--job-id', '871', '--raw', '--subdir', 'DAGS_FOLDER/data_ingestion_hw_1_ex.py', '--cfg-path', '/tmp/tmp3akvfmue', '--error-file', '/tmp/tmpjdkiabm2']
[2022-02-10 15:42:34,127] {standard_task_runner.py:77} INFO - Job 871: Subtask local_to_gcs_task
[2022-02-10 15:42:34,211] {logging_mixin.py:109} INFO - Running <TaskInstance: ex_1_data_ingestion_gcs_dag_v3.local_to_gcs_task scheduled__2021-06-01T00:00:00+00:00 [running]> on host 276a0ad90304
[2022-02-10 15:42:34,263] {warnings.py:110} WARNING - /home/***/.local/lib/python3.7/site-packages/***/utils/context.py:152: AirflowContextDeprecationWarning: Accessing 'execution_date' from the template is deprecated and will be removed in a future version. Please use 'data_interval_start' or 'logical_date' instead.
  warnings.warn(_create_deprecation_warning(key, self._deprecation_replacements[key]))

[2022-02-10 15:42:34,290] {taskinstance.py:1426} INFO - Exporting the following env vars:
AIRFLOW_CTX_DAG_OWNER=***
AIRFLOW_CTX_DAG_ID=ex_1_data_ingestion_gcs_dag_v3
AIRFLOW_CTX_TASK_ID=local_to_gcs_task
AIRFLOW_CTX_EXECUTION_DATE=2021-06-01T00:00:00+00:00
AIRFLOW_CTX_DAG_RUN_ID=scheduled__2021-06-01T00:00:00+00:00
[2022-02-10 15:42:39,771] {python.py:175} INFO - Done. Returned value was: None
[2022-02-10 15:42:39,791] {taskinstance.py:1277} INFO - Marking task as SUCCESS. dag_id=ex_1_data_ingestion_gcs_dag_v3, task_id=local_to_gcs_task, execution_date=20210601T000000, start_date=20220210T154234, end_date=20220210T154239
[2022-02-10 15:42:39,834] {local_task_job.py:154} INFO - Task exited with return code 0
[2022-02-10 15:42:39,872] {local_task_job.py:264} INFO - 0 downstream tasks scheduled from follow-on schedule check
[2022-02-10 16:45:04,839] {taskinstance.py:1032} INFO - Dependencies all met for <TaskInstance: ex_1_data_ingestion_gcs_dag_v3.local_to_gcs_task scheduled__2021-06-01T00:00:00+00:00 [queued]>
[2022-02-10 16:45:04,865] {taskinstance.py:1032} INFO - Dependencies all met for <TaskInstance: ex_1_data_ingestion_gcs_dag_v3.local_to_gcs_task scheduled__2021-06-01T00:00:00+00:00 [queued]>
[2022-02-10 16:45:04,867] {taskinstance.py:1238} INFO - 
--------------------------------------------------------------------------------
[2022-02-10 16:45:04,868] {taskinstance.py:1239} INFO - Starting attempt 1 of 1
[2022-02-10 16:45:04,870] {taskinstance.py:1240} INFO - 
--------------------------------------------------------------------------------
[2022-02-10 16:45:04,905] {taskinstance.py:1259} INFO - Executing <Task(PythonOperator): local_to_gcs_task> on 2021-06-01 00:00:00+00:00
[2022-02-10 16:45:04,917] {standard_task_runner.py:52} INFO - Started process 1038 to run task
[2022-02-10 16:45:04,934] {standard_task_runner.py:76} INFO - Running: ['***', 'tasks', 'run', 'ex_1_data_ingestion_gcs_dag_v3', 'local_to_gcs_task', 'scheduled__2021-06-01T00:00:00+00:00', '--job-id', '987', '--raw', '--subdir', 'DAGS_FOLDER/data_ingestion_hw_1_ex.py', '--cfg-path', '/tmp/tmpzld3u407', '--error-file', '/tmp/tmp00_9s4md']
[2022-02-10 16:45:04,952] {standard_task_runner.py:77} INFO - Job 987: Subtask local_to_gcs_task
[2022-02-10 16:45:05,132] {logging_mixin.py:109} INFO - Running <TaskInstance: ex_1_data_ingestion_gcs_dag_v3.local_to_gcs_task scheduled__2021-06-01T00:00:00+00:00 [running]> on host 106a34111faf
[2022-02-10 16:45:05,235] {warnings.py:110} WARNING - /home/***/.local/lib/python3.7/site-packages/***/utils/context.py:152: AirflowContextDeprecationWarning: Accessing 'execution_date' from the template is deprecated and will be removed in a future version. Please use 'data_interval_start' or 'logical_date' instead.
  warnings.warn(_create_deprecation_warning(key, self._deprecation_replacements[key]))

[2022-02-10 16:45:05,278] {taskinstance.py:1426} INFO - Exporting the following env vars:
AIRFLOW_CTX_DAG_OWNER=***
AIRFLOW_CTX_DAG_ID=ex_1_data_ingestion_gcs_dag_v3
AIRFLOW_CTX_TASK_ID=local_to_gcs_task
AIRFLOW_CTX_EXECUTION_DATE=2021-06-01T00:00:00+00:00
AIRFLOW_CTX_DAG_RUN_ID=scheduled__2021-06-01T00:00:00+00:00
[2022-02-10 16:45:26,089] {python.py:175} INFO - Done. Returned value was: None
[2022-02-10 16:45:26,123] {taskinstance.py:1277} INFO - Marking task as SUCCESS. dag_id=ex_1_data_ingestion_gcs_dag_v3, task_id=local_to_gcs_task, execution_date=20210601T000000, start_date=20220210T164504, end_date=20220210T164526
[2022-02-10 16:45:26,188] {local_task_job.py:154} INFO - Task exited with return code 0
[2022-02-10 16:45:26,234] {local_task_job.py:264} INFO - 0 downstream tasks scheduled from follow-on schedule check
