[2022-02-02 18:22:56,507] {taskinstance.py:1032} INFO - Dependencies all met for <TaskInstance: ex_1_data_ingestion_gcs_dag_v3.local_to_gcs_task scheduled__2019-07-01T00:00:00+00:00 [queued]>
[2022-02-02 18:22:56,524] {taskinstance.py:1032} INFO - Dependencies all met for <TaskInstance: ex_1_data_ingestion_gcs_dag_v3.local_to_gcs_task scheduled__2019-07-01T00:00:00+00:00 [queued]>
[2022-02-02 18:22:56,525] {taskinstance.py:1238} INFO - 
--------------------------------------------------------------------------------
[2022-02-02 18:22:56,526] {taskinstance.py:1239} INFO - Starting attempt 1 of 1
[2022-02-02 18:22:56,527] {taskinstance.py:1240} INFO - 
--------------------------------------------------------------------------------
[2022-02-02 18:22:56,547] {taskinstance.py:1259} INFO - Executing <Task(PythonOperator): local_to_gcs_task> on 2019-07-01 00:00:00+00:00
[2022-02-02 18:22:56,556] {standard_task_runner.py:52} INFO - Started process 9132 to run task
[2022-02-02 18:22:56,562] {standard_task_runner.py:76} INFO - Running: ['***', 'tasks', 'run', 'ex_1_data_ingestion_gcs_dag_v3', 'local_to_gcs_task', 'scheduled__2019-07-01T00:00:00+00:00', '--job-id', '324', '--raw', '--subdir', 'DAGS_FOLDER/data_ingestion_hw_1_ex.py', '--cfg-path', '/tmp/tmpmj5l060n', '--error-file', '/tmp/tmphx45txy5']
[2022-02-02 18:22:56,564] {standard_task_runner.py:77} INFO - Job 324: Subtask local_to_gcs_task
[2022-02-02 18:22:56,637] {logging_mixin.py:109} INFO - Running <TaskInstance: ex_1_data_ingestion_gcs_dag_v3.local_to_gcs_task scheduled__2019-07-01T00:00:00+00:00 [running]> on host 700aeb16bae0
[2022-02-02 18:22:56,687] {warnings.py:110} WARNING - /home/***/.local/lib/python3.7/site-packages/***/utils/context.py:152: AirflowContextDeprecationWarning: Accessing 'execution_date' from the template is deprecated and will be removed in a future version. Please use 'data_interval_start' or 'logical_date' instead.
  warnings.warn(_create_deprecation_warning(key, self._deprecation_replacements[key]))

[2022-02-02 18:22:56,719] {taskinstance.py:1426} INFO - Exporting the following env vars:
AIRFLOW_CTX_DAG_OWNER=***
AIRFLOW_CTX_DAG_ID=ex_1_data_ingestion_gcs_dag_v3
AIRFLOW_CTX_TASK_ID=local_to_gcs_task
AIRFLOW_CTX_EXECUTION_DATE=2019-07-01T00:00:00+00:00
AIRFLOW_CTX_DAG_RUN_ID=scheduled__2019-07-01T00:00:00+00:00
[2022-02-02 18:23:07,810] {python.py:175} INFO - Done. Returned value was: None
[2022-02-02 18:23:07,844] {taskinstance.py:1277} INFO - Marking task as SUCCESS. dag_id=ex_1_data_ingestion_gcs_dag_v3, task_id=local_to_gcs_task, execution_date=20190701T000000, start_date=20220202T182256, end_date=20220202T182307
[2022-02-02 18:23:07,876] {local_task_job.py:154} INFO - Task exited with return code 0
[2022-02-02 18:23:07,918] {local_task_job.py:264} INFO - 0 downstream tasks scheduled from follow-on schedule check
[2022-02-10 13:00:38,290] {taskinstance.py:1032} INFO - Dependencies all met for <TaskInstance: ex_1_data_ingestion_gcs_dag_v3.local_to_gcs_task scheduled__2019-07-01T00:00:00+00:00 [queued]>
[2022-02-10 13:00:38,313] {taskinstance.py:1032} INFO - Dependencies all met for <TaskInstance: ex_1_data_ingestion_gcs_dag_v3.local_to_gcs_task scheduled__2019-07-01T00:00:00+00:00 [queued]>
[2022-02-10 13:00:38,314] {taskinstance.py:1238} INFO - 
--------------------------------------------------------------------------------
[2022-02-10 13:00:38,315] {taskinstance.py:1239} INFO - Starting attempt 1 of 1
[2022-02-10 13:00:38,316] {taskinstance.py:1240} INFO - 
--------------------------------------------------------------------------------
[2022-02-10 13:00:38,338] {taskinstance.py:1259} INFO - Executing <Task(PythonOperator): local_to_gcs_task> on 2019-07-01 00:00:00+00:00
[2022-02-10 13:00:38,345] {standard_task_runner.py:52} INFO - Started process 1360 to run task
[2022-02-10 13:00:38,351] {standard_task_runner.py:76} INFO - Running: ['***', 'tasks', 'run', 'ex_1_data_ingestion_gcs_dag_v3', 'local_to_gcs_task', 'scheduled__2019-07-01T00:00:00+00:00', '--job-id', '680', '--raw', '--subdir', 'DAGS_FOLDER/data_ingestion_hw_1_ex.py', '--cfg-path', '/tmp/tmpq1u8yx0v', '--error-file', '/tmp/tmpz9rt1tpd']
[2022-02-10 13:00:38,358] {standard_task_runner.py:77} INFO - Job 680: Subtask local_to_gcs_task
[2022-02-10 13:00:38,474] {logging_mixin.py:109} INFO - Running <TaskInstance: ex_1_data_ingestion_gcs_dag_v3.local_to_gcs_task scheduled__2019-07-01T00:00:00+00:00 [running]> on host e30f201fae61
[2022-02-10 13:00:38,554] {warnings.py:110} WARNING - /home/***/.local/lib/python3.7/site-packages/***/utils/context.py:152: AirflowContextDeprecationWarning: Accessing 'execution_date' from the template is deprecated and will be removed in a future version. Please use 'data_interval_start' or 'logical_date' instead.
  warnings.warn(_create_deprecation_warning(key, self._deprecation_replacements[key]))

[2022-02-10 13:00:38,604] {taskinstance.py:1426} INFO - Exporting the following env vars:
AIRFLOW_CTX_DAG_OWNER=***
AIRFLOW_CTX_DAG_ID=ex_1_data_ingestion_gcs_dag_v3
AIRFLOW_CTX_TASK_ID=local_to_gcs_task
AIRFLOW_CTX_EXECUTION_DATE=2019-07-01T00:00:00+00:00
AIRFLOW_CTX_DAG_RUN_ID=scheduled__2019-07-01T00:00:00+00:00
[2022-02-10 13:00:49,733] {python.py:175} INFO - Done. Returned value was: None
[2022-02-10 13:00:49,750] {taskinstance.py:1277} INFO - Marking task as SUCCESS. dag_id=ex_1_data_ingestion_gcs_dag_v3, task_id=local_to_gcs_task, execution_date=20190701T000000, start_date=20220210T130038, end_date=20220210T130049
[2022-02-10 13:00:49,796] {local_task_job.py:154} INFO - Task exited with return code 0
[2022-02-10 13:00:49,854] {local_task_job.py:264} INFO - 0 downstream tasks scheduled from follow-on schedule check
[2022-02-10 15:35:21,938] {taskinstance.py:1032} INFO - Dependencies all met for <TaskInstance: ex_1_data_ingestion_gcs_dag_v3.local_to_gcs_task scheduled__2019-07-01T00:00:00+00:00 [queued]>
[2022-02-10 15:35:21,981] {taskinstance.py:1032} INFO - Dependencies all met for <TaskInstance: ex_1_data_ingestion_gcs_dag_v3.local_to_gcs_task scheduled__2019-07-01T00:00:00+00:00 [queued]>
[2022-02-10 15:35:21,983] {taskinstance.py:1238} INFO - 
--------------------------------------------------------------------------------
[2022-02-10 15:35:21,984] {taskinstance.py:1239} INFO - Starting attempt 1 of 1
[2022-02-10 15:35:21,986] {taskinstance.py:1240} INFO - 
--------------------------------------------------------------------------------
[2022-02-10 15:35:22,019] {taskinstance.py:1259} INFO - Executing <Task(PythonOperator): local_to_gcs_task> on 2019-07-01 00:00:00+00:00
[2022-02-10 15:35:22,035] {standard_task_runner.py:52} INFO - Started process 448 to run task
[2022-02-10 15:35:22,050] {standard_task_runner.py:76} INFO - Running: ['***', 'tasks', 'run', 'ex_1_data_ingestion_gcs_dag_v3', 'local_to_gcs_task', 'scheduled__2019-07-01T00:00:00+00:00', '--job-id', '800', '--raw', '--subdir', 'DAGS_FOLDER/data_ingestion_hw_1_ex.py', '--cfg-path', '/tmp/tmprde1r169', '--error-file', '/tmp/tmpja09zpzk']
[2022-02-10 15:35:22,054] {standard_task_runner.py:77} INFO - Job 800: Subtask local_to_gcs_task
[2022-02-10 15:35:22,179] {logging_mixin.py:109} INFO - Running <TaskInstance: ex_1_data_ingestion_gcs_dag_v3.local_to_gcs_task scheduled__2019-07-01T00:00:00+00:00 [running]> on host 276a0ad90304
[2022-02-10 15:35:22,250] {warnings.py:110} WARNING - /home/***/.local/lib/python3.7/site-packages/***/utils/context.py:152: AirflowContextDeprecationWarning: Accessing 'execution_date' from the template is deprecated and will be removed in a future version. Please use 'data_interval_start' or 'logical_date' instead.
  warnings.warn(_create_deprecation_warning(key, self._deprecation_replacements[key]))

[2022-02-10 15:35:22,294] {taskinstance.py:1426} INFO - Exporting the following env vars:
AIRFLOW_CTX_DAG_OWNER=***
AIRFLOW_CTX_DAG_ID=ex_1_data_ingestion_gcs_dag_v3
AIRFLOW_CTX_TASK_ID=local_to_gcs_task
AIRFLOW_CTX_EXECUTION_DATE=2019-07-01T00:00:00+00:00
AIRFLOW_CTX_DAG_RUN_ID=scheduled__2019-07-01T00:00:00+00:00
[2022-02-10 15:35:33,388] {python.py:175} INFO - Done. Returned value was: None
[2022-02-10 15:35:33,410] {taskinstance.py:1277} INFO - Marking task as SUCCESS. dag_id=ex_1_data_ingestion_gcs_dag_v3, task_id=local_to_gcs_task, execution_date=20190701T000000, start_date=20220210T153521, end_date=20220210T153533
[2022-02-10 15:35:33,471] {local_task_job.py:154} INFO - Task exited with return code 0
[2022-02-10 15:35:33,510] {local_task_job.py:264} INFO - 0 downstream tasks scheduled from follow-on schedule check
[2022-02-10 16:51:26,526] {taskinstance.py:1032} INFO - Dependencies all met for <TaskInstance: ex_1_data_ingestion_gcs_dag_v3.local_to_gcs_task scheduled__2019-07-01T00:00:00+00:00 [queued]>
[2022-02-10 16:51:26,545] {taskinstance.py:1032} INFO - Dependencies all met for <TaskInstance: ex_1_data_ingestion_gcs_dag_v3.local_to_gcs_task scheduled__2019-07-01T00:00:00+00:00 [queued]>
[2022-02-10 16:51:26,546] {taskinstance.py:1238} INFO - 
--------------------------------------------------------------------------------
[2022-02-10 16:51:26,547] {taskinstance.py:1239} INFO - Starting attempt 1 of 1
[2022-02-10 16:51:26,548] {taskinstance.py:1240} INFO - 
--------------------------------------------------------------------------------
[2022-02-10 16:51:26,569] {taskinstance.py:1259} INFO - Executing <Task(PythonOperator): local_to_gcs_task> on 2019-07-01 00:00:00+00:00
[2022-02-10 16:51:26,577] {standard_task_runner.py:52} INFO - Started process 1400 to run task
[2022-02-10 16:51:26,583] {standard_task_runner.py:76} INFO - Running: ['***', 'tasks', 'run', 'ex_1_data_ingestion_gcs_dag_v3', 'local_to_gcs_task', 'scheduled__2019-07-01T00:00:00+00:00', '--job-id', '1007', '--raw', '--subdir', 'DAGS_FOLDER/data_ingestion_hw_1_ex.py', '--cfg-path', '/tmp/tmpo5o90h1d', '--error-file', '/tmp/tmpquagi8yw']
[2022-02-10 16:51:26,585] {standard_task_runner.py:77} INFO - Job 1007: Subtask local_to_gcs_task
[2022-02-10 16:51:26,684] {logging_mixin.py:109} INFO - Running <TaskInstance: ex_1_data_ingestion_gcs_dag_v3.local_to_gcs_task scheduled__2019-07-01T00:00:00+00:00 [running]> on host 106a34111faf
[2022-02-10 16:51:26,743] {warnings.py:110} WARNING - /home/***/.local/lib/python3.7/site-packages/***/utils/context.py:152: AirflowContextDeprecationWarning: Accessing 'execution_date' from the template is deprecated and will be removed in a future version. Please use 'data_interval_start' or 'logical_date' instead.
  warnings.warn(_create_deprecation_warning(key, self._deprecation_replacements[key]))

[2022-02-10 16:51:26,782] {taskinstance.py:1426} INFO - Exporting the following env vars:
AIRFLOW_CTX_DAG_OWNER=***
AIRFLOW_CTX_DAG_ID=ex_1_data_ingestion_gcs_dag_v3
AIRFLOW_CTX_TASK_ID=local_to_gcs_task
AIRFLOW_CTX_EXECUTION_DATE=2019-07-01T00:00:00+00:00
AIRFLOW_CTX_DAG_RUN_ID=scheduled__2019-07-01T00:00:00+00:00
[2022-02-10 16:52:38,588] {taskinstance.py:1700} ERROR - Task failed with exception
Traceback (most recent call last):
  File "/home/airflow/.local/lib/python3.7/site-packages/urllib3/connectionpool.py", line 706, in urlopen
    chunked=chunked,
  File "/home/airflow/.local/lib/python3.7/site-packages/urllib3/connectionpool.py", line 445, in _make_request
    six.raise_from(e, None)
  File "<string>", line 3, in raise_from
  File "/home/airflow/.local/lib/python3.7/site-packages/urllib3/connectionpool.py", line 440, in _make_request
    httplib_response = conn.getresponse()
  File "/usr/local/lib/python3.7/http/client.py", line 1373, in getresponse
    response.begin()
  File "/usr/local/lib/python3.7/http/client.py", line 319, in begin
    version, status, reason = self._read_status()
  File "/usr/local/lib/python3.7/http/client.py", line 288, in _read_status
    raise RemoteDisconnected("Remote end closed connection without"
http.client.RemoteDisconnected: Remote end closed connection without response

During handling of the above exception, another exception occurred:

Traceback (most recent call last):
  File "/home/airflow/.local/lib/python3.7/site-packages/requests/adapters.py", line 449, in send
    timeout=timeout
  File "/home/airflow/.local/lib/python3.7/site-packages/urllib3/connectionpool.py", line 756, in urlopen
    method, url, error=e, _pool=self, _stacktrace=sys.exc_info()[2]
  File "/home/airflow/.local/lib/python3.7/site-packages/urllib3/util/retry.py", line 532, in increment
    raise six.reraise(type(error), error, _stacktrace)
  File "/home/airflow/.local/lib/python3.7/site-packages/urllib3/packages/six.py", line 769, in reraise
    raise value.with_traceback(tb)
  File "/home/airflow/.local/lib/python3.7/site-packages/urllib3/connectionpool.py", line 706, in urlopen
    chunked=chunked,
  File "/home/airflow/.local/lib/python3.7/site-packages/urllib3/connectionpool.py", line 445, in _make_request
    six.raise_from(e, None)
  File "<string>", line 3, in raise_from
  File "/home/airflow/.local/lib/python3.7/site-packages/urllib3/connectionpool.py", line 440, in _make_request
    httplib_response = conn.getresponse()
  File "/usr/local/lib/python3.7/http/client.py", line 1373, in getresponse
    response.begin()
  File "/usr/local/lib/python3.7/http/client.py", line 319, in begin
    version, status, reason = self._read_status()
  File "/usr/local/lib/python3.7/http/client.py", line 288, in _read_status
    raise RemoteDisconnected("Remote end closed connection without"
urllib3.exceptions.ProtocolError: ('Connection aborted.', RemoteDisconnected('Remote end closed connection without response'))

During handling of the above exception, another exception occurred:

Traceback (most recent call last):
  File "/home/airflow/.local/lib/python3.7/site-packages/airflow/models/taskinstance.py", line 1329, in _run_raw_task
    self._execute_task_with_callbacks(context)
  File "/home/airflow/.local/lib/python3.7/site-packages/airflow/models/taskinstance.py", line 1455, in _execute_task_with_callbacks
    result = self._execute_task(context, self.task)
  File "/home/airflow/.local/lib/python3.7/site-packages/airflow/models/taskinstance.py", line 1511, in _execute_task
    result = execute_callable(context=context)
  File "/home/airflow/.local/lib/python3.7/site-packages/airflow/operators/python.py", line 174, in execute
    return_value = self.execute_callable()
  File "/home/airflow/.local/lib/python3.7/site-packages/airflow/operators/python.py", line 185, in execute_callable
    return self.python_callable(*self.op_args, **self.op_kwargs)
  File "/opt/airflow/dags/data_ingestion_hw_1_ex.py", line 53, in upload_to_gcs
    blob.upload_from_filename(local_file)
  File "/home/airflow/.local/lib/python3.7/site-packages/google/cloud/storage/blob.py", line 2735, in upload_from_filename
    retry=retry,
  File "/home/airflow/.local/lib/python3.7/site-packages/google/cloud/storage/blob.py", line 2594, in upload_from_file
    retry=retry,
  File "/home/airflow/.local/lib/python3.7/site-packages/google/cloud/storage/blob.py", line 2412, in _do_upload
    retry=retry,
  File "/home/airflow/.local/lib/python3.7/site-packages/google/cloud/storage/blob.py", line 2242, in _do_resumable_upload
    response = upload.transmit_next_chunk(transport, timeout=timeout)
  File "/home/airflow/.local/lib/python3.7/site-packages/google/resumable_media/requests/upload.py", line 516, in transmit_next_chunk
    retriable_request, self._get_status_code, self._retry_strategy
  File "/home/airflow/.local/lib/python3.7/site-packages/google/resumable_media/requests/_request_helpers.py", line 170, in wait_and_retry
    raise error
  File "/home/airflow/.local/lib/python3.7/site-packages/google/resumable_media/requests/_request_helpers.py", line 147, in wait_and_retry
    response = func()
  File "/home/airflow/.local/lib/python3.7/site-packages/google/resumable_media/requests/upload.py", line 508, in retriable_request
    method, url, data=payload, headers=headers, timeout=timeout
  File "/home/airflow/.local/lib/python3.7/site-packages/google/auth/transport/requests.py", line 486, in request
    **kwargs
  File "/home/airflow/.local/lib/python3.7/site-packages/requests/sessions.py", line 542, in request
    resp = self.send(prep, **send_kwargs)
  File "/home/airflow/.local/lib/python3.7/site-packages/requests/sessions.py", line 655, in send
    r = adapter.send(request, **kwargs)
  File "/home/airflow/.local/lib/python3.7/site-packages/requests/adapters.py", line 498, in send
    raise ConnectionError(err, request=request)
requests.exceptions.ConnectionError: ('Connection aborted.', RemoteDisconnected('Remote end closed connection without response'))
[2022-02-10 16:52:38,702] {taskinstance.py:1277} INFO - Marking task as FAILED. dag_id=ex_1_data_ingestion_gcs_dag_v3, task_id=local_to_gcs_task, execution_date=20190701T000000, start_date=20220210T165126, end_date=20220210T165238
[2022-02-10 16:52:38,805] {standard_task_runner.py:92} ERROR - Failed to execute job 1007 for task local_to_gcs_task
Traceback (most recent call last):
  File "/home/airflow/.local/lib/python3.7/site-packages/urllib3/connectionpool.py", line 706, in urlopen
    chunked=chunked,
  File "/home/airflow/.local/lib/python3.7/site-packages/urllib3/connectionpool.py", line 445, in _make_request
    six.raise_from(e, None)
  File "<string>", line 3, in raise_from
  File "/home/airflow/.local/lib/python3.7/site-packages/urllib3/connectionpool.py", line 440, in _make_request
    httplib_response = conn.getresponse()
  File "/usr/local/lib/python3.7/http/client.py", line 1373, in getresponse
    response.begin()
  File "/usr/local/lib/python3.7/http/client.py", line 319, in begin
    version, status, reason = self._read_status()
  File "/usr/local/lib/python3.7/http/client.py", line 288, in _read_status
    raise RemoteDisconnected("Remote end closed connection without"
http.client.RemoteDisconnected: Remote end closed connection without response

During handling of the above exception, another exception occurred:

Traceback (most recent call last):
  File "/home/airflow/.local/lib/python3.7/site-packages/requests/adapters.py", line 449, in send
    timeout=timeout
  File "/home/airflow/.local/lib/python3.7/site-packages/urllib3/connectionpool.py", line 756, in urlopen
    method, url, error=e, _pool=self, _stacktrace=sys.exc_info()[2]
  File "/home/airflow/.local/lib/python3.7/site-packages/urllib3/util/retry.py", line 532, in increment
    raise six.reraise(type(error), error, _stacktrace)
  File "/home/airflow/.local/lib/python3.7/site-packages/urllib3/packages/six.py", line 769, in reraise
    raise value.with_traceback(tb)
  File "/home/airflow/.local/lib/python3.7/site-packages/urllib3/connectionpool.py", line 706, in urlopen
    chunked=chunked,
  File "/home/airflow/.local/lib/python3.7/site-packages/urllib3/connectionpool.py", line 445, in _make_request
    six.raise_from(e, None)
  File "<string>", line 3, in raise_from
  File "/home/airflow/.local/lib/python3.7/site-packages/urllib3/connectionpool.py", line 440, in _make_request
    httplib_response = conn.getresponse()
  File "/usr/local/lib/python3.7/http/client.py", line 1373, in getresponse
    response.begin()
  File "/usr/local/lib/python3.7/http/client.py", line 319, in begin
    version, status, reason = self._read_status()
  File "/usr/local/lib/python3.7/http/client.py", line 288, in _read_status
    raise RemoteDisconnected("Remote end closed connection without"
urllib3.exceptions.ProtocolError: ('Connection aborted.', RemoteDisconnected('Remote end closed connection without response'))

During handling of the above exception, another exception occurred:

Traceback (most recent call last):
  File "/home/airflow/.local/lib/python3.7/site-packages/airflow/task/task_runner/standard_task_runner.py", line 85, in _start_by_fork
    args.func(args, dag=self.dag)
  File "/home/airflow/.local/lib/python3.7/site-packages/airflow/cli/cli_parser.py", line 48, in command
    return func(*args, **kwargs)
  File "/home/airflow/.local/lib/python3.7/site-packages/airflow/utils/cli.py", line 92, in wrapper
    return f(*args, **kwargs)
  File "/home/airflow/.local/lib/python3.7/site-packages/airflow/cli/commands/task_command.py", line 298, in task_run
    _run_task_by_selected_method(args, dag, ti)
  File "/home/airflow/.local/lib/python3.7/site-packages/airflow/cli/commands/task_command.py", line 107, in _run_task_by_selected_method
    _run_raw_task(args, ti)
  File "/home/airflow/.local/lib/python3.7/site-packages/airflow/cli/commands/task_command.py", line 184, in _run_raw_task
    error_file=args.error_file,
  File "/home/airflow/.local/lib/python3.7/site-packages/airflow/utils/session.py", line 70, in wrapper
    return func(*args, session=session, **kwargs)
  File "/home/airflow/.local/lib/python3.7/site-packages/airflow/models/taskinstance.py", line 1329, in _run_raw_task
    self._execute_task_with_callbacks(context)
  File "/home/airflow/.local/lib/python3.7/site-packages/airflow/models/taskinstance.py", line 1455, in _execute_task_with_callbacks
    result = self._execute_task(context, self.task)
  File "/home/airflow/.local/lib/python3.7/site-packages/airflow/models/taskinstance.py", line 1511, in _execute_task
    result = execute_callable(context=context)
  File "/home/airflow/.local/lib/python3.7/site-packages/airflow/operators/python.py", line 174, in execute
    return_value = self.execute_callable()
  File "/home/airflow/.local/lib/python3.7/site-packages/airflow/operators/python.py", line 185, in execute_callable
    return self.python_callable(*self.op_args, **self.op_kwargs)
  File "/opt/airflow/dags/data_ingestion_hw_1_ex.py", line 53, in upload_to_gcs
    blob.upload_from_filename(local_file)
  File "/home/airflow/.local/lib/python3.7/site-packages/google/cloud/storage/blob.py", line 2735, in upload_from_filename
    retry=retry,
  File "/home/airflow/.local/lib/python3.7/site-packages/google/cloud/storage/blob.py", line 2594, in upload_from_file
    retry=retry,
  File "/home/airflow/.local/lib/python3.7/site-packages/google/cloud/storage/blob.py", line 2412, in _do_upload
    retry=retry,
  File "/home/airflow/.local/lib/python3.7/site-packages/google/cloud/storage/blob.py", line 2242, in _do_resumable_upload
    response = upload.transmit_next_chunk(transport, timeout=timeout)
  File "/home/airflow/.local/lib/python3.7/site-packages/google/resumable_media/requests/upload.py", line 516, in transmit_next_chunk
    retriable_request, self._get_status_code, self._retry_strategy
  File "/home/airflow/.local/lib/python3.7/site-packages/google/resumable_media/requests/_request_helpers.py", line 170, in wait_and_retry
    raise error
  File "/home/airflow/.local/lib/python3.7/site-packages/google/resumable_media/requests/_request_helpers.py", line 147, in wait_and_retry
    response = func()
  File "/home/airflow/.local/lib/python3.7/site-packages/google/resumable_media/requests/upload.py", line 508, in retriable_request
    method, url, data=payload, headers=headers, timeout=timeout
  File "/home/airflow/.local/lib/python3.7/site-packages/google/auth/transport/requests.py", line 486, in request
    **kwargs
  File "/home/airflow/.local/lib/python3.7/site-packages/requests/sessions.py", line 542, in request
    resp = self.send(prep, **send_kwargs)
  File "/home/airflow/.local/lib/python3.7/site-packages/requests/sessions.py", line 655, in send
    r = adapter.send(request, **kwargs)
  File "/home/airflow/.local/lib/python3.7/site-packages/requests/adapters.py", line 498, in send
    raise ConnectionError(err, request=request)
requests.exceptions.ConnectionError: ('Connection aborted.', RemoteDisconnected('Remote end closed connection without response'))
[2022-02-10 16:52:38,938] {local_task_job.py:154} INFO - Task exited with return code 1
[2022-02-10 16:52:39,055] {local_task_job.py:264} INFO - 0 downstream tasks scheduled from follow-on schedule check
