[2022-02-09 17:22:03,751] {taskinstance.py:1032} INFO - Dependencies all met for <TaskInstance: data_2_gcs_dag.gcs_2_gcs_task manual__2022-02-09T17:22:01.944213+00:00 [queued]>
[2022-02-09 17:22:03,763] {taskinstance.py:1032} INFO - Dependencies all met for <TaskInstance: data_2_gcs_dag.gcs_2_gcs_task manual__2022-02-09T17:22:01.944213+00:00 [queued]>
[2022-02-09 17:22:03,764] {taskinstance.py:1238} INFO - 
--------------------------------------------------------------------------------
[2022-02-09 17:22:03,765] {taskinstance.py:1239} INFO - Starting attempt 1 of 2
[2022-02-09 17:22:03,766] {taskinstance.py:1240} INFO - 
--------------------------------------------------------------------------------
[2022-02-09 17:22:03,778] {taskinstance.py:1259} INFO - Executing <Task(GCSToGCSOperator): gcs_2_gcs_task> on 2022-02-09 17:22:01.944213+00:00
[2022-02-09 17:22:03,783] {standard_task_runner.py:52} INFO - Started process 3470 to run task
[2022-02-09 17:22:03,787] {standard_task_runner.py:76} INFO - Running: ['***', 'tasks', 'run', 'data_2_gcs_dag', 'gcs_2_gcs_task', 'manual__2022-02-09T17:22:01.944213+00:00', '--job-id', '645', '--raw', '--subdir', 'DAGS_FOLDER/data-2-gcs-dag.py', '--cfg-path', '/tmp/tmp2jsgwucr', '--error-file', '/tmp/tmpzmv1f9ua']
[2022-02-09 17:22:03,789] {standard_task_runner.py:77} INFO - Job 645: Subtask gcs_2_gcs_task
[2022-02-09 17:22:03,847] {logging_mixin.py:109} INFO - Running <TaskInstance: data_2_gcs_dag.gcs_2_gcs_task manual__2022-02-09T17:22:01.944213+00:00 [running]> on host f5a18e7ac2e5
[2022-02-09 17:22:03,908] {taskinstance.py:1426} INFO - Exporting the following env vars:
AIRFLOW_CTX_DAG_OWNER=***
AIRFLOW_CTX_DAG_ID=data_2_gcs_dag
AIRFLOW_CTX_TASK_ID=gcs_2_gcs_task
AIRFLOW_CTX_EXECUTION_DATE=2022-02-09T17:22:01.944213+00:00
AIRFLOW_CTX_DAG_RUN_ID=manual__2022-02-09T17:22:01.944213+00:00
[2022-02-09 17:22:03,910] {crypto.py:82} WARNING - empty cryptography key - values will not be stored encrypted.
[2022-02-09 17:22:03,925] {taskinstance.py:1700} ERROR - Task failed with exception
Traceback (most recent call last):
  File "/home/airflow/.local/lib/python3.7/site-packages/airflow/models/taskinstance.py", line 1329, in _run_raw_task
    self._execute_task_with_callbacks(context)
  File "/home/airflow/.local/lib/python3.7/site-packages/airflow/models/taskinstance.py", line 1455, in _execute_task_with_callbacks
    result = self._execute_task(context, self.task)
  File "/home/airflow/.local/lib/python3.7/site-packages/airflow/models/taskinstance.py", line 1511, in _execute_task
    result = execute_callable(context=context)
  File "/home/airflow/.local/lib/python3.7/site-packages/airflow/providers/google/cloud/transfers/gcs_to_gcs.py", line 268, in execute
    raise AirflowException("You can't have two empty strings inside source_object")
airflow.exceptions.AirflowException: You can't have two empty strings inside source_object
[2022-02-09 17:22:03,934] {taskinstance.py:1277} INFO - Marking task as UP_FOR_RETRY. dag_id=data_2_gcs_dag, task_id=gcs_2_gcs_task, execution_date=20220209T172201, start_date=20220209T172203, end_date=20220209T172203
[2022-02-09 17:22:03,948] {standard_task_runner.py:92} ERROR - Failed to execute job 645 for task gcs_2_gcs_task
Traceback (most recent call last):
  File "/home/airflow/.local/lib/python3.7/site-packages/airflow/task/task_runner/standard_task_runner.py", line 85, in _start_by_fork
    args.func(args, dag=self.dag)
  File "/home/airflow/.local/lib/python3.7/site-packages/airflow/cli/cli_parser.py", line 48, in command
    return func(*args, **kwargs)
  File "/home/airflow/.local/lib/python3.7/site-packages/airflow/utils/cli.py", line 92, in wrapper
    return f(*args, **kwargs)
  File "/home/airflow/.local/lib/python3.7/site-packages/airflow/cli/commands/task_command.py", line 298, in task_run
    _run_task_by_selected_method(args, dag, ti)
  File "/home/airflow/.local/lib/python3.7/site-packages/airflow/cli/commands/task_command.py", line 107, in _run_task_by_selected_method
    _run_raw_task(args, ti)
  File "/home/airflow/.local/lib/python3.7/site-packages/airflow/cli/commands/task_command.py", line 184, in _run_raw_task
    error_file=args.error_file,
  File "/home/airflow/.local/lib/python3.7/site-packages/airflow/utils/session.py", line 70, in wrapper
    return func(*args, session=session, **kwargs)
  File "/home/airflow/.local/lib/python3.7/site-packages/airflow/models/taskinstance.py", line 1329, in _run_raw_task
    self._execute_task_with_callbacks(context)
  File "/home/airflow/.local/lib/python3.7/site-packages/airflow/models/taskinstance.py", line 1455, in _execute_task_with_callbacks
    result = self._execute_task(context, self.task)
  File "/home/airflow/.local/lib/python3.7/site-packages/airflow/models/taskinstance.py", line 1511, in _execute_task
    result = execute_callable(context=context)
  File "/home/airflow/.local/lib/python3.7/site-packages/airflow/providers/google/cloud/transfers/gcs_to_gcs.py", line 268, in execute
    raise AirflowException("You can't have two empty strings inside source_object")
airflow.exceptions.AirflowException: You can't have two empty strings inside source_object
[2022-02-09 17:22:04,000] {local_task_job.py:154} INFO - Task exited with return code 1
[2022-02-09 17:22:04,061] {local_task_job.py:264} INFO - 0 downstream tasks scheduled from follow-on schedule check
