[2022-02-03 15:22:33,687] {taskinstance.py:1032} INFO - Dependencies all met for <TaskInstance: FHV_data_ingestion_gcs_dag.download_dataset_task scheduled__2021-12-01T00:00:00+00:00 [queued]>
[2022-02-03 15:22:33,708] {taskinstance.py:1032} INFO - Dependencies all met for <TaskInstance: FHV_data_ingestion_gcs_dag.download_dataset_task scheduled__2021-12-01T00:00:00+00:00 [queued]>
[2022-02-03 15:22:33,710] {taskinstance.py:1238} INFO - 
--------------------------------------------------------------------------------
[2022-02-03 15:22:33,712] {taskinstance.py:1239} INFO - Starting attempt 1 of 1
[2022-02-03 15:22:33,714] {taskinstance.py:1240} INFO - 
--------------------------------------------------------------------------------
[2022-02-03 15:22:33,732] {taskinstance.py:1259} INFO - Executing <Task(BashOperator): download_dataset_task> on 2021-12-01 00:00:00+00:00
[2022-02-03 15:22:33,743] {standard_task_runner.py:52} INFO - Started process 3838 to run task
[2022-02-03 15:22:33,749] {standard_task_runner.py:76} INFO - Running: ['***', 'tasks', 'run', 'FHV_data_ingestion_gcs_dag', 'download_dataset_task', 'scheduled__2021-12-01T00:00:00+00:00', '--job-id', '625', '--raw', '--subdir', 'DAGS_FOLDER/FHV_injection_dag.py', '--cfg-path', '/tmp/tmp9740r5wi', '--error-file', '/tmp/tmp_avozgxw']
[2022-02-03 15:22:33,750] {standard_task_runner.py:77} INFO - Job 625: Subtask download_dataset_task
[2022-02-03 15:22:33,819] {logging_mixin.py:109} INFO - Running <TaskInstance: FHV_data_ingestion_gcs_dag.download_dataset_task scheduled__2021-12-01T00:00:00+00:00 [running]> on host 700aeb16bae0
[2022-02-03 15:22:33,857] {warnings.py:110} WARNING - /home/***/.local/lib/python3.7/site-packages/***/utils/context.py:152: AirflowContextDeprecationWarning: Accessing 'execution_date' from the template is deprecated and will be removed in a future version. Please use 'data_interval_start' or 'logical_date' instead.
  warnings.warn(_create_deprecation_warning(key, self._deprecation_replacements[key]))

[2022-02-03 15:22:33,880] {taskinstance.py:1426} INFO - Exporting the following env vars:
AIRFLOW_CTX_DAG_OWNER=***
AIRFLOW_CTX_DAG_ID=FHV_data_ingestion_gcs_dag
AIRFLOW_CTX_TASK_ID=download_dataset_task
AIRFLOW_CTX_EXECUTION_DATE=2021-12-01T00:00:00+00:00
AIRFLOW_CTX_DAG_RUN_ID=scheduled__2021-12-01T00:00:00+00:00
[2022-02-03 15:22:33,882] {subprocess.py:62} INFO - Tmp dir root location: 
 /tmp
[2022-02-03 15:22:33,883] {subprocess.py:74} INFO - Running command: ['bash', '-c', 'curl -sSLf https://nyc-tlc.s3.amazonaws.com/trip+data/fhv_tripdata_2021-12.csv > /opt/***/fhv_tripdata_2021-12.csv']
[2022-02-03 15:22:33,893] {subprocess.py:85} INFO - Output:
[2022-02-03 15:22:34,403] {subprocess.py:89} INFO - curl: (22) The requested URL returned error: 404 Not Found
[2022-02-03 15:22:34,405] {subprocess.py:93} INFO - Command exited with return code 22
[2022-02-03 15:22:34,430] {taskinstance.py:1700} ERROR - Task failed with exception
Traceback (most recent call last):
  File "/home/airflow/.local/lib/python3.7/site-packages/airflow/models/taskinstance.py", line 1329, in _run_raw_task
    self._execute_task_with_callbacks(context)
  File "/home/airflow/.local/lib/python3.7/site-packages/airflow/models/taskinstance.py", line 1455, in _execute_task_with_callbacks
    result = self._execute_task(context, self.task)
  File "/home/airflow/.local/lib/python3.7/site-packages/airflow/models/taskinstance.py", line 1511, in _execute_task
    result = execute_callable(context=context)
  File "/home/airflow/.local/lib/python3.7/site-packages/airflow/operators/bash.py", line 188, in execute
    f'Bash command failed. The command returned a non-zero exit code {result.exit_code}.'
airflow.exceptions.AirflowException: Bash command failed. The command returned a non-zero exit code 22.
[2022-02-03 15:22:34,440] {taskinstance.py:1277} INFO - Marking task as FAILED. dag_id=FHV_data_ingestion_gcs_dag, task_id=download_dataset_task, execution_date=20211201T000000, start_date=20220203T152233, end_date=20220203T152234
[2022-02-03 15:22:34,456] {standard_task_runner.py:92} ERROR - Failed to execute job 625 for task download_dataset_task
Traceback (most recent call last):
  File "/home/airflow/.local/lib/python3.7/site-packages/airflow/task/task_runner/standard_task_runner.py", line 85, in _start_by_fork
    args.func(args, dag=self.dag)
  File "/home/airflow/.local/lib/python3.7/site-packages/airflow/cli/cli_parser.py", line 48, in command
    return func(*args, **kwargs)
  File "/home/airflow/.local/lib/python3.7/site-packages/airflow/utils/cli.py", line 92, in wrapper
    return f(*args, **kwargs)
  File "/home/airflow/.local/lib/python3.7/site-packages/airflow/cli/commands/task_command.py", line 298, in task_run
    _run_task_by_selected_method(args, dag, ti)
  File "/home/airflow/.local/lib/python3.7/site-packages/airflow/cli/commands/task_command.py", line 107, in _run_task_by_selected_method
    _run_raw_task(args, ti)
  File "/home/airflow/.local/lib/python3.7/site-packages/airflow/cli/commands/task_command.py", line 184, in _run_raw_task
    error_file=args.error_file,
  File "/home/airflow/.local/lib/python3.7/site-packages/airflow/utils/session.py", line 70, in wrapper
    return func(*args, session=session, **kwargs)
  File "/home/airflow/.local/lib/python3.7/site-packages/airflow/models/taskinstance.py", line 1329, in _run_raw_task
    self._execute_task_with_callbacks(context)
  File "/home/airflow/.local/lib/python3.7/site-packages/airflow/models/taskinstance.py", line 1455, in _execute_task_with_callbacks
    result = self._execute_task(context, self.task)
  File "/home/airflow/.local/lib/python3.7/site-packages/airflow/models/taskinstance.py", line 1511, in _execute_task
    result = execute_callable(context=context)
  File "/home/airflow/.local/lib/python3.7/site-packages/airflow/operators/bash.py", line 188, in execute
    f'Bash command failed. The command returned a non-zero exit code {result.exit_code}.'
airflow.exceptions.AirflowException: Bash command failed. The command returned a non-zero exit code 22.
[2022-02-03 15:22:34,508] {local_task_job.py:154} INFO - Task exited with return code 1
[2022-02-03 15:22:34,555] {local_task_job.py:264} INFO - 0 downstream tasks scheduled from follow-on schedule check
