[2022-02-03 14:34:27,487] {taskinstance.py:1032} INFO - Dependencies all met for <TaskInstance: FHV_data_ingestion_gcs_dag.download_dataset_task manual__2022-02-03T14:28:53.227061+00:00 [queued]>
[2022-02-03 14:34:27,504] {taskinstance.py:1032} INFO - Dependencies all met for <TaskInstance: FHV_data_ingestion_gcs_dag.download_dataset_task manual__2022-02-03T14:28:53.227061+00:00 [queued]>
[2022-02-03 14:34:27,506] {taskinstance.py:1238} INFO - 
--------------------------------------------------------------------------------
[2022-02-03 14:34:27,507] {taskinstance.py:1239} INFO - Starting attempt 1 of 1
[2022-02-03 14:34:27,508] {taskinstance.py:1240} INFO - 
--------------------------------------------------------------------------------
[2022-02-03 14:34:27,533] {taskinstance.py:1259} INFO - Executing <Task(BashOperator): download_dataset_task> on 2022-02-03 14:28:53.227061+00:00
[2022-02-03 14:34:27,538] {standard_task_runner.py:52} INFO - Started process 595 to run task
[2022-02-03 14:34:27,543] {standard_task_runner.py:76} INFO - Running: ['***', 'tasks', 'run', 'FHV_data_ingestion_gcs_dag', 'download_dataset_task', 'manual__2022-02-03T14:28:53.227061+00:00', '--job-id', '424', '--raw', '--subdir', 'DAGS_FOLDER/FHV_injection_dag.py', '--cfg-path', '/tmp/tmp343mr8um', '--error-file', '/tmp/tmp0cep0q6j']
[2022-02-03 14:34:27,544] {standard_task_runner.py:77} INFO - Job 424: Subtask download_dataset_task
[2022-02-03 14:34:27,601] {logging_mixin.py:109} INFO - Running <TaskInstance: FHV_data_ingestion_gcs_dag.download_dataset_task manual__2022-02-03T14:28:53.227061+00:00 [running]> on host 700aeb16bae0
[2022-02-03 14:34:27,638] {warnings.py:110} WARNING - /home/***/.local/lib/python3.7/site-packages/***/utils/context.py:152: AirflowContextDeprecationWarning: Accessing 'execution_date' from the template is deprecated and will be removed in a future version. Please use 'data_interval_start' or 'logical_date' instead.
  warnings.warn(_create_deprecation_warning(key, self._deprecation_replacements[key]))

[2022-02-03 14:34:27,659] {taskinstance.py:1426} INFO - Exporting the following env vars:
AIRFLOW_CTX_DAG_OWNER=***
AIRFLOW_CTX_DAG_ID=FHV_data_ingestion_gcs_dag
AIRFLOW_CTX_TASK_ID=download_dataset_task
AIRFLOW_CTX_EXECUTION_DATE=2022-02-03T14:28:53.227061+00:00
AIRFLOW_CTX_DAG_RUN_ID=manual__2022-02-03T14:28:53.227061+00:00
[2022-02-03 14:34:27,661] {subprocess.py:62} INFO - Tmp dir root location: 
 /tmp
[2022-02-03 14:34:27,662] {subprocess.py:74} INFO - Running command: ['bash', '-c', 'curl -sSLf https://nyc-tlc.s3.amazonaws.com/trip+data/fhv_tripdata_2022-02.csv > /opt/***/fhv_tripdata_2022-02.csv']
[2022-02-03 14:34:27,673] {subprocess.py:85} INFO - Output:
[2022-02-03 14:34:28,236] {subprocess.py:89} INFO - curl: (22) The requested URL returned error: 404 Not Found
[2022-02-03 14:34:28,243] {subprocess.py:93} INFO - Command exited with return code 22
[2022-02-03 14:34:28,300] {taskinstance.py:1700} ERROR - Task failed with exception
Traceback (most recent call last):
  File "/home/airflow/.local/lib/python3.7/site-packages/airflow/models/taskinstance.py", line 1329, in _run_raw_task
    self._execute_task_with_callbacks(context)
  File "/home/airflow/.local/lib/python3.7/site-packages/airflow/models/taskinstance.py", line 1455, in _execute_task_with_callbacks
    result = self._execute_task(context, self.task)
  File "/home/airflow/.local/lib/python3.7/site-packages/airflow/models/taskinstance.py", line 1511, in _execute_task
    result = execute_callable(context=context)
  File "/home/airflow/.local/lib/python3.7/site-packages/airflow/operators/bash.py", line 188, in execute
    f'Bash command failed. The command returned a non-zero exit code {result.exit_code}.'
airflow.exceptions.AirflowException: Bash command failed. The command returned a non-zero exit code 22.
[2022-02-03 14:34:28,343] {taskinstance.py:1277} INFO - Marking task as FAILED. dag_id=FHV_data_ingestion_gcs_dag, task_id=download_dataset_task, execution_date=20220203T142853, start_date=20220203T143427, end_date=20220203T143428
[2022-02-03 14:34:28,379] {standard_task_runner.py:92} ERROR - Failed to execute job 424 for task download_dataset_task
Traceback (most recent call last):
  File "/home/airflow/.local/lib/python3.7/site-packages/airflow/task/task_runner/standard_task_runner.py", line 85, in _start_by_fork
    args.func(args, dag=self.dag)
  File "/home/airflow/.local/lib/python3.7/site-packages/airflow/cli/cli_parser.py", line 48, in command
    return func(*args, **kwargs)
  File "/home/airflow/.local/lib/python3.7/site-packages/airflow/utils/cli.py", line 92, in wrapper
    return f(*args, **kwargs)
  File "/home/airflow/.local/lib/python3.7/site-packages/airflow/cli/commands/task_command.py", line 298, in task_run
    _run_task_by_selected_method(args, dag, ti)
  File "/home/airflow/.local/lib/python3.7/site-packages/airflow/cli/commands/task_command.py", line 107, in _run_task_by_selected_method
    _run_raw_task(args, ti)
  File "/home/airflow/.local/lib/python3.7/site-packages/airflow/cli/commands/task_command.py", line 184, in _run_raw_task
    error_file=args.error_file,
  File "/home/airflow/.local/lib/python3.7/site-packages/airflow/utils/session.py", line 70, in wrapper
    return func(*args, session=session, **kwargs)
  File "/home/airflow/.local/lib/python3.7/site-packages/airflow/models/taskinstance.py", line 1329, in _run_raw_task
    self._execute_task_with_callbacks(context)
  File "/home/airflow/.local/lib/python3.7/site-packages/airflow/models/taskinstance.py", line 1455, in _execute_task_with_callbacks
    result = self._execute_task(context, self.task)
  File "/home/airflow/.local/lib/python3.7/site-packages/airflow/models/taskinstance.py", line 1511, in _execute_task
    result = execute_callable(context=context)
  File "/home/airflow/.local/lib/python3.7/site-packages/airflow/operators/bash.py", line 188, in execute
    f'Bash command failed. The command returned a non-zero exit code {result.exit_code}.'
airflow.exceptions.AirflowException: Bash command failed. The command returned a non-zero exit code 22.
[2022-02-03 14:34:28,446] {local_task_job.py:154} INFO - Task exited with return code 1
[2022-02-03 14:34:28,531] {local_task_job.py:264} INFO - 0 downstream tasks scheduled from follow-on schedule check
