[2022-02-03 14:46:20,029] {taskinstance.py:1032} INFO - Dependencies all met for <TaskInstance: FHV_data_ingestion_gcs_dag.remove_datasets_task scheduled__2019-09-01T00:00:00+00:00 [queued]>
[2022-02-03 14:46:20,041] {taskinstance.py:1032} INFO - Dependencies all met for <TaskInstance: FHV_data_ingestion_gcs_dag.remove_datasets_task scheduled__2019-09-01T00:00:00+00:00 [queued]>
[2022-02-03 14:46:20,041] {taskinstance.py:1238} INFO - 
--------------------------------------------------------------------------------
[2022-02-03 14:46:20,042] {taskinstance.py:1239} INFO - Starting attempt 1 of 1
[2022-02-03 14:46:20,043] {taskinstance.py:1240} INFO - 
--------------------------------------------------------------------------------
[2022-02-03 14:46:20,054] {taskinstance.py:1259} INFO - Executing <Task(BashOperator): remove_datasets_task> on 2019-09-01 00:00:00+00:00
[2022-02-03 14:46:20,060] {standard_task_runner.py:52} INFO - Started process 1304 to run task
[2022-02-03 14:46:20,063] {standard_task_runner.py:76} INFO - Running: ['***', 'tasks', 'run', 'FHV_data_ingestion_gcs_dag', 'remove_datasets_task', 'scheduled__2019-09-01T00:00:00+00:00', '--job-id', '454', '--raw', '--subdir', 'DAGS_FOLDER/FHV_injection_dag.py', '--cfg-path', '/tmp/tmp5dh_wx2s', '--error-file', '/tmp/tmp9qu_n98u']
[2022-02-03 14:46:20,065] {standard_task_runner.py:77} INFO - Job 454: Subtask remove_datasets_task
[2022-02-03 14:46:20,133] {logging_mixin.py:109} INFO - Running <TaskInstance: FHV_data_ingestion_gcs_dag.remove_datasets_task scheduled__2019-09-01T00:00:00+00:00 [running]> on host 700aeb16bae0
[2022-02-03 14:46:20,169] {warnings.py:110} WARNING - /home/***/.local/lib/python3.7/site-packages/***/utils/context.py:152: AirflowContextDeprecationWarning: Accessing 'execution_date' from the template is deprecated and will be removed in a future version. Please use 'data_interval_start' or 'logical_date' instead.
  warnings.warn(_create_deprecation_warning(key, self._deprecation_replacements[key]))

[2022-02-03 14:46:20,188] {taskinstance.py:1426} INFO - Exporting the following env vars:
AIRFLOW_CTX_DAG_OWNER=***
AIRFLOW_CTX_DAG_ID=FHV_data_ingestion_gcs_dag
AIRFLOW_CTX_TASK_ID=remove_datasets_task
AIRFLOW_CTX_EXECUTION_DATE=2019-09-01T00:00:00+00:00
AIRFLOW_CTX_DAG_RUN_ID=scheduled__2019-09-01T00:00:00+00:00
[2022-02-03 14:46:20,190] {subprocess.py:62} INFO - Tmp dir root location: 
 /tmp
[2022-02-03 14:46:20,191] {subprocess.py:74} INFO - Running command: ['bash', '-c', 'rm fhv_tripdata_2019-09.csv fhv_tripdata_2019-09.parquet']
[2022-02-03 14:46:20,204] {subprocess.py:85} INFO - Output:
[2022-02-03 14:46:20,208] {subprocess.py:89} INFO - rm: cannot remove 'fhv_tripdata_2019-09.csv': No such file or directory
[2022-02-03 14:46:20,209] {subprocess.py:89} INFO - rm: cannot remove 'fhv_tripdata_2019-09.parquet': No such file or directory
[2022-02-03 14:46:20,210] {subprocess.py:93} INFO - Command exited with return code 1
[2022-02-03 14:46:20,226] {taskinstance.py:1700} ERROR - Task failed with exception
Traceback (most recent call last):
  File "/home/airflow/.local/lib/python3.7/site-packages/airflow/models/taskinstance.py", line 1329, in _run_raw_task
    self._execute_task_with_callbacks(context)
  File "/home/airflow/.local/lib/python3.7/site-packages/airflow/models/taskinstance.py", line 1455, in _execute_task_with_callbacks
    result = self._execute_task(context, self.task)
  File "/home/airflow/.local/lib/python3.7/site-packages/airflow/models/taskinstance.py", line 1511, in _execute_task
    result = execute_callable(context=context)
  File "/home/airflow/.local/lib/python3.7/site-packages/airflow/operators/bash.py", line 188, in execute
    f'Bash command failed. The command returned a non-zero exit code {result.exit_code}.'
airflow.exceptions.AirflowException: Bash command failed. The command returned a non-zero exit code 1.
[2022-02-03 14:46:20,233] {taskinstance.py:1277} INFO - Marking task as FAILED. dag_id=FHV_data_ingestion_gcs_dag, task_id=remove_datasets_task, execution_date=20190901T000000, start_date=20220203T144620, end_date=20220203T144620
[2022-02-03 14:46:20,246] {standard_task_runner.py:92} ERROR - Failed to execute job 454 for task remove_datasets_task
Traceback (most recent call last):
  File "/home/airflow/.local/lib/python3.7/site-packages/airflow/task/task_runner/standard_task_runner.py", line 85, in _start_by_fork
    args.func(args, dag=self.dag)
  File "/home/airflow/.local/lib/python3.7/site-packages/airflow/cli/cli_parser.py", line 48, in command
    return func(*args, **kwargs)
  File "/home/airflow/.local/lib/python3.7/site-packages/airflow/utils/cli.py", line 92, in wrapper
    return f(*args, **kwargs)
  File "/home/airflow/.local/lib/python3.7/site-packages/airflow/cli/commands/task_command.py", line 298, in task_run
    _run_task_by_selected_method(args, dag, ti)
  File "/home/airflow/.local/lib/python3.7/site-packages/airflow/cli/commands/task_command.py", line 107, in _run_task_by_selected_method
    _run_raw_task(args, ti)
  File "/home/airflow/.local/lib/python3.7/site-packages/airflow/cli/commands/task_command.py", line 184, in _run_raw_task
    error_file=args.error_file,
  File "/home/airflow/.local/lib/python3.7/site-packages/airflow/utils/session.py", line 70, in wrapper
    return func(*args, session=session, **kwargs)
  File "/home/airflow/.local/lib/python3.7/site-packages/airflow/models/taskinstance.py", line 1329, in _run_raw_task
    self._execute_task_with_callbacks(context)
  File "/home/airflow/.local/lib/python3.7/site-packages/airflow/models/taskinstance.py", line 1455, in _execute_task_with_callbacks
    result = self._execute_task(context, self.task)
  File "/home/airflow/.local/lib/python3.7/site-packages/airflow/models/taskinstance.py", line 1511, in _execute_task
    result = execute_callable(context=context)
  File "/home/airflow/.local/lib/python3.7/site-packages/airflow/operators/bash.py", line 188, in execute
    f'Bash command failed. The command returned a non-zero exit code {result.exit_code}.'
airflow.exceptions.AirflowException: Bash command failed. The command returned a non-zero exit code 1.
[2022-02-03 14:46:20,279] {local_task_job.py:154} INFO - Task exited with return code 1
[2022-02-03 14:46:20,319] {local_task_job.py:264} INFO - 0 downstream tasks scheduled from follow-on schedule check
